Exception on /index [GET]
Traceback (most recent call last):
  File "d:\python27\lib\site-packages\flask\app.py", line 1982, in wsgi_app
    response = self.full_dispatch_request()
  File "d:\python27\lib\site-packages\flask\app.py", line 1614, in full_dispatch_request
    rv = self.handle_user_exception(e)
  File "d:\python27\lib\site-packages\flask\app.py", line 1517, in handle_user_exception
    reraise(exc_type, exc_value, tb)
  File "d:\python27\lib\site-packages\flask\app.py", line 1612, in full_dispatch_request
    rv = self.dispatch_request()
  File "d:\python27\lib\site-packages\flask\app.py", line 1598, in dispatch_request
    return self.view_functions[rule.endpoint](**req.view_args)
  File "d:\python27\lib\site-packages\flask_login\utils.py", line 228, in decorated_view
    return func(*args, **kwargs)
  File "D:\Python27\microblog\app\routes.py", line 12, in index
    form =PostForm()
NameError: global name 'PostForm' is not defined
Microblog startup
Exception on /explore [GET]
Traceback (most recent call last):
  File "d:\python27\lib\site-packages\flask\app.py", line 1982, in wsgi_app
    response = self.full_dispatch_request()
  File "d:\python27\lib\site-packages\flask\app.py", line 1614, in full_dispatch_request
    rv = self.handle_user_exception(e)
  File "d:\python27\lib\site-packages\flask\app.py", line 1517, in handle_user_exception
    reraise(exc_type, exc_value, tb)
  File "d:\python27\lib\site-packages\flask\app.py", line 1612, in full_dispatch_request
    rv = self.dispatch_request()
  File "d:\python27\lib\site-packages\flask\app.py", line 1598, in dispatch_request
    return self.view_functions[rule.endpoint](**req.view_args)
  File "d:\python27\lib\site-packages\flask_login\utils.py", line 228, in decorated_view
    return func(*args, **kwargs)
  File "D:\Python27\microblog\app\routes.py", line 114, in explore
    posts = Post.query.order_by(Post.timestamp.desc()).all()
NameError: global name 'Post' is not defined
Exception on /explore [GET]
Traceback (most recent call last):
  File "d:\python27\lib\site-packages\flask\app.py", line 1982, in wsgi_app
    response = self.full_dispatch_request()
  File "d:\python27\lib\site-packages\flask\app.py", line 1614, in full_dispatch_request
    rv = self.handle_user_exception(e)
  File "d:\python27\lib\site-packages\flask\app.py", line 1517, in handle_user_exception
    reraise(exc_type, exc_value, tb)
  File "d:\python27\lib\site-packages\flask\app.py", line 1612, in full_dispatch_request
    rv = self.dispatch_request()
  File "d:\python27\lib\site-packages\flask\app.py", line 1598, in dispatch_request
    return self.view_functions[rule.endpoint](**req.view_args)
  File "d:\python27\lib\site-packages\flask_login\utils.py", line 228, in decorated_view
    return func(*args, **kwargs)
  File "D:\Python27\microblog\app\routes.py", line 114, in explore
    posts = Post.query.order_by(Post.timestamp.desc()).all()
NameError: global name 'Post' is not defined
Microblog startup
Microblog startup
Microblog startup
Microblog startup
Microblog startup
Exception on /index [POST]
Traceback (most recent call last):
  File "d:\python27\lib\site-packages\flask\app.py", line 1982, in wsgi_app
    response = self.full_dispatch_request()
  File "d:\python27\lib\site-packages\flask\app.py", line 1614, in full_dispatch_request
    rv = self.handle_user_exception(e)
  File "d:\python27\lib\site-packages\flask\app.py", line 1517, in handle_user_exception
    reraise(exc_type, exc_value, tb)
  File "d:\python27\lib\site-packages\flask\app.py", line 1612, in full_dispatch_request
    rv = self.dispatch_request()
  File "d:\python27\lib\site-packages\flask\app.py", line 1598, in dispatch_request
    return self.view_functions[rule.endpoint](**req.view_args)
  File "d:\python27\lib\site-packages\flask_login\utils.py", line 228, in decorated_view
    return func(*args, **kwargs)
  File "D:\Python27\microblog\app\routes.py", line 14, in index
    post = Post(body=form.post.data,author=current_user)
  File "<string>", line 4, in __init__
  File "d:\python27\lib\site-packages\sqlalchemy\orm\state.py", line 414, in _initialize_instance
    manager.dispatch.init_failure(self, args, kwargs)
  File "d:\python27\lib\site-packages\sqlalchemy\util\langhelpers.py", line 66, in __exit__
    compat.reraise(exc_type, exc_value, exc_tb)
  File "d:\python27\lib\site-packages\sqlalchemy\orm\state.py", line 411, in _initialize_instance
    return manager.original_init(*mixed[1:], **kwargs)
  File "d:\python27\lib\site-packages\sqlalchemy\ext\declarative\base.py", line 657, in _declarative_constructor
    (k, cls_.__name__))
TypeError: 'author' is an invalid keyword argument for Post
Microblog startup
Microblog startup
Exception on /index [POST]
Traceback (most recent call last):
  File "d:\python27\lib\site-packages\flask\app.py", line 1982, in wsgi_app
    response = self.full_dispatch_request()
  File "d:\python27\lib\site-packages\flask\app.py", line 1614, in full_dispatch_request
    rv = self.handle_user_exception(e)
  File "d:\python27\lib\site-packages\flask\app.py", line 1517, in handle_user_exception
    reraise(exc_type, exc_value, tb)
  File "d:\python27\lib\site-packages\flask\app.py", line 1612, in full_dispatch_request
    rv = self.dispatch_request()
  File "d:\python27\lib\site-packages\flask\app.py", line 1598, in dispatch_request
    return self.view_functions[rule.endpoint](**req.view_args)
  File "d:\python27\lib\site-packages\flask_login\utils.py", line 228, in decorated_view
    return func(*args, **kwargs)
  File "D:\Python27\microblog\app\routes.py", line 14, in index
    post = Post(body=form.post.data,author=current_user)
  File "<string>", line 4, in __init__
  File "d:\python27\lib\site-packages\sqlalchemy\orm\state.py", line 414, in _initialize_instance
    manager.dispatch.init_failure(self, args, kwargs)
  File "d:\python27\lib\site-packages\sqlalchemy\util\langhelpers.py", line 66, in __exit__
    compat.reraise(exc_type, exc_value, exc_tb)
  File "d:\python27\lib\site-packages\sqlalchemy\orm\state.py", line 411, in _initialize_instance
    return manager.original_init(*mixed[1:], **kwargs)
  File "d:\python27\lib\site-packages\sqlalchemy\ext\declarative\base.py", line 657, in _declarative_constructor
    (k, cls_.__name__))
TypeError: 'author' is an invalid keyword argument for Post
Microblog startup
Exception on /index [POST]
Traceback (most recent call last):
  File "d:\python27\lib\site-packages\flask\app.py", line 1982, in wsgi_app
    response = self.full_dispatch_request()
  File "d:\python27\lib\site-packages\flask\app.py", line 1614, in full_dispatch_request
    rv = self.handle_user_exception(e)
  File "d:\python27\lib\site-packages\flask\app.py", line 1517, in handle_user_exception
    reraise(exc_type, exc_value, tb)
  File "d:\python27\lib\site-packages\flask\app.py", line 1612, in full_dispatch_request
    rv = self.dispatch_request()
  File "d:\python27\lib\site-packages\flask\app.py", line 1598, in dispatch_request
    return self.view_functions[rule.endpoint](**req.view_args)
  File "d:\python27\lib\site-packages\flask_login\utils.py", line 228, in decorated_view
    return func(*args, **kwargs)
  File "D:\Python27\microblog\app\routes.py", line 16, in index
    db.session.commit()
  File "d:\python27\lib\site-packages\sqlalchemy\orm\scoping.py", line 157, in do
    return getattr(self.registry(), name)(*args, **kwargs)
  File "d:\python27\lib\site-packages\sqlalchemy\orm\session.py", line 906, in commit
    self.transaction.commit()
  File "d:\python27\lib\site-packages\sqlalchemy\orm\session.py", line 461, in commit
    self._prepare_impl()
  File "d:\python27\lib\site-packages\sqlalchemy\orm\session.py", line 441, in _prepare_impl
    self.session.flush()
  File "d:\python27\lib\site-packages\sqlalchemy\orm\session.py", line 2171, in flush
    self._flush(objects)
  File "d:\python27\lib\site-packages\sqlalchemy\orm\session.py", line 2291, in _flush
    transaction.rollback(_capture_exception=True)
  File "d:\python27\lib\site-packages\sqlalchemy\util\langhelpers.py", line 66, in __exit__
    compat.reraise(exc_type, exc_value, exc_tb)
  File "d:\python27\lib\site-packages\sqlalchemy\orm\session.py", line 2255, in _flush
    flush_context.execute()
  File "d:\python27\lib\site-packages\sqlalchemy\orm\unitofwork.py", line 389, in execute
    rec.execute(self)
  File "d:\python27\lib\site-packages\sqlalchemy\orm\unitofwork.py", line 548, in execute
    uow
  File "d:\python27\lib\site-packages\sqlalchemy\orm\persistence.py", line 181, in save_obj
    mapper, table, insert)
  File "d:\python27\lib\site-packages\sqlalchemy\orm\persistence.py", line 835, in _emit_insert_statements
    execute(statement, params)
  File "d:\python27\lib\site-packages\sqlalchemy\engine\base.py", line 945, in execute
    return meth(self, multiparams, params)
  File "d:\python27\lib\site-packages\sqlalchemy\sql\elements.py", line 263, in _execute_on_connection
    return connection._execute_clauseelement(self, multiparams, params)
  File "d:\python27\lib\site-packages\sqlalchemy\engine\base.py", line 1053, in _execute_clauseelement
    compiled_sql, distilled_params
  File "d:\python27\lib\site-packages\sqlalchemy\engine\base.py", line 1189, in _execute_context
    context)
  File "d:\python27\lib\site-packages\sqlalchemy\engine\base.py", line 1402, in _handle_dbapi_exception
    exc_info
  File "d:\python27\lib\site-packages\sqlalchemy\util\compat.py", line 203, in raise_from_cause
    reraise(type(exception), exception, tb=exc_tb, cause=cause)
  File "d:\python27\lib\site-packages\sqlalchemy\engine\base.py", line 1182, in _execute_context
    context)
  File "d:\python27\lib\site-packages\sqlalchemy\engine\default.py", line 470, in do_execute
    cursor.execute(statement, parameters)
InterfaceError: <unprintable InterfaceError object>
Microblog startup
