Exception on /index [POST]
Traceback (most recent call last):
  File "d:\python27\lib\site-packages\flask\app.py", line 1982, in wsgi_app
    response = self.full_dispatch_request()
  File "d:\python27\lib\site-packages\flask\app.py", line 1614, in full_dispatch_request
    rv = self.handle_user_exception(e)
  File "d:\python27\lib\site-packages\flask\app.py", line 1517, in handle_user_exception
    reraise(exc_type, exc_value, tb)
  File "d:\python27\lib\site-packages\flask\app.py", line 1612, in full_dispatch_request
    rv = self.dispatch_request()
  File "d:\python27\lib\site-packages\flask\app.py", line 1598, in dispatch_request
    return self.view_functions[rule.endpoint](**req.view_args)
  File "d:\python27\lib\site-packages\flask_login\utils.py", line 228, in decorated_view
    return func(*args, **kwargs)
  File "D:\Python27\microblog\app\routes.py", line 14, in index
    post = Post(body=form.post.data,author=current_user)
  File "<string>", line 4, in __init__
  File "d:\python27\lib\site-packages\sqlalchemy\orm\state.py", line 414, in _initialize_instance
    manager.dispatch.init_failure(self, args, kwargs)
  File "d:\python27\lib\site-packages\sqlalchemy\util\langhelpers.py", line 66, in __exit__
    compat.reraise(exc_type, exc_value, exc_tb)
  File "d:\python27\lib\site-packages\sqlalchemy\orm\state.py", line 411, in _initialize_instance
    return manager.original_init(*mixed[1:], **kwargs)
  File "d:\python27\lib\site-packages\sqlalchemy\ext\declarative\base.py", line 657, in _declarative_constructor
    (k, cls_.__name__))
TypeError: 'author' is an invalid keyword argument for Post
Microblog startup
Exception on /index [POST]
Traceback (most recent call last):
  File "d:\python27\lib\site-packages\flask\app.py", line 1982, in wsgi_app
    response = self.full_dispatch_request()
  File "d:\python27\lib\site-packages\flask\app.py", line 1614, in full_dispatch_request
    rv = self.handle_user_exception(e)
  File "d:\python27\lib\site-packages\flask\app.py", line 1517, in handle_user_exception
    reraise(exc_type, exc_value, tb)
  File "d:\python27\lib\site-packages\flask\app.py", line 1612, in full_dispatch_request
    rv = self.dispatch_request()
  File "d:\python27\lib\site-packages\flask\app.py", line 1598, in dispatch_request
    return self.view_functions[rule.endpoint](**req.view_args)
  File "d:\python27\lib\site-packages\flask_login\utils.py", line 228, in decorated_view
    return func(*args, **kwargs)
  File "D:\Python27\microblog\app\routes.py", line 20, in index
    post = Post(body=form.post.data,author=current_user)
  File "<string>", line 4, in __init__
  File "d:\python27\lib\site-packages\sqlalchemy\orm\state.py", line 414, in _initialize_instance
    manager.dispatch.init_failure(self, args, kwargs)
  File "d:\python27\lib\site-packages\sqlalchemy\util\langhelpers.py", line 66, in __exit__
    compat.reraise(exc_type, exc_value, exc_tb)
  File "d:\python27\lib\site-packages\sqlalchemy\orm\state.py", line 411, in _initialize_instance
    return manager.original_init(*mixed[1:], **kwargs)
  File "d:\python27\lib\site-packages\sqlalchemy\ext\declarative\base.py", line 657, in _declarative_constructor
    (k, cls_.__name__))
TypeError: 'author' is an invalid keyword argument for Post
Microblog startup
Microblog startup
Exception on /index [GET]
Traceback (most recent call last):
  File "d:\python27\lib\site-packages\flask\app.py", line 1982, in wsgi_app
    response = self.full_dispatch_request()
  File "d:\python27\lib\site-packages\flask\app.py", line 1614, in full_dispatch_request
    rv = self.handle_user_exception(e)
  File "d:\python27\lib\site-packages\flask\app.py", line 1517, in handle_user_exception
    reraise(exc_type, exc_value, tb)
  File "d:\python27\lib\site-packages\flask\app.py", line 1612, in full_dispatch_request
    rv = self.dispatch_request()
  File "d:\python27\lib\site-packages\flask\app.py", line 1598, in dispatch_request
    return self.view_functions[rule.endpoint](**req.view_args)
  File "d:\python27\lib\site-packages\flask_login\utils.py", line 228, in decorated_view
    return func(*args, **kwargs)
  File "D:\Python27\microblog\app\routes.py", line 27, in index
    page,app.config['POSTS_PER_PAGE'],False)
KeyError: 'POSTS_PER_PAGE'
Exception on /index [GET]
Traceback (most recent call last):
  File "d:\python27\lib\site-packages\flask\app.py", line 1982, in wsgi_app
    response = self.full_dispatch_request()
  File "d:\python27\lib\site-packages\flask\app.py", line 1614, in full_dispatch_request
    rv = self.handle_user_exception(e)
  File "d:\python27\lib\site-packages\flask\app.py", line 1517, in handle_user_exception
    reraise(exc_type, exc_value, tb)
  File "d:\python27\lib\site-packages\flask\app.py", line 1612, in full_dispatch_request
    rv = self.dispatch_request()
  File "d:\python27\lib\site-packages\flask\app.py", line 1598, in dispatch_request
    return self.view_functions[rule.endpoint](**req.view_args)
  File "d:\python27\lib\site-packages\flask_login\utils.py", line 228, in decorated_view
    return func(*args, **kwargs)
  File "D:\Python27\microblog\app\routes.py", line 27, in index
    page,app.config['POSTS_PER_PAGE'],False)
KeyError: 'POSTS_PER_PAGE'
Exception on /index [GET]
Traceback (most recent call last):
  File "d:\python27\lib\site-packages\flask\app.py", line 1982, in wsgi_app
    response = self.full_dispatch_request()
  File "d:\python27\lib\site-packages\flask\app.py", line 1614, in full_dispatch_request
    rv = self.handle_user_exception(e)
  File "d:\python27\lib\site-packages\flask\app.py", line 1517, in handle_user_exception
    reraise(exc_type, exc_value, tb)
  File "d:\python27\lib\site-packages\flask\app.py", line 1612, in full_dispatch_request
    rv = self.dispatch_request()
  File "d:\python27\lib\site-packages\flask\app.py", line 1598, in dispatch_request
    return self.view_functions[rule.endpoint](**req.view_args)
  File "d:\python27\lib\site-packages\flask_login\utils.py", line 228, in decorated_view
    return func(*args, **kwargs)
  File "D:\Python27\microblog\app\routes.py", line 27, in index
    page,app.config['POSTS_PER_PAGE'],False)
KeyError: 'POSTS_PER_PAGE'
Microblog startup
Microblog startup
Microblog startup
Exception on /login [GET]
Traceback (most recent call last):
  File "d:\python27\lib\site-packages\flask\app.py", line 1982, in wsgi_app
    response = self.full_dispatch_request()
  File "d:\python27\lib\site-packages\flask\app.py", line 1614, in full_dispatch_request
    rv = self.handle_user_exception(e)
  File "d:\python27\lib\site-packages\flask\app.py", line 1517, in handle_user_exception
    reraise(exc_type, exc_value, tb)
  File "d:\python27\lib\site-packages\flask\app.py", line 1612, in full_dispatch_request
    rv = self.dispatch_request()
  File "d:\python27\lib\site-packages\flask\app.py", line 1598, in dispatch_request
    return self.view_functions[rule.endpoint](**req.view_args)
  File "D:\Python27\microblog\app\routes.py", line 49, in login
    return render_template('login.html',title='Sign In',form=form)
  File "d:\python27\lib\site-packages\flask\templating.py", line 134, in render_template
    context, ctx.app)
  File "d:\python27\lib\site-packages\flask\templating.py", line 116, in _render
    rv = template.render(context)
  File "d:\python27\lib\site-packages\jinja2\environment.py", line 1008, in render
    return self.environment.handle_exception(exc_info, True)
  File "d:\python27\lib\site-packages\jinja2\environment.py", line 780, in handle_exception
    reraise(exc_type, exc_value, tb)
  File "D:\Python27\microblog\app\templates\login.html", line 1, in top-level template code
    {% extends "base.html" %}
  File "D:\Python27\microblog\app\templates\base.html", line 32, in top-level template code
    {% block content %}{% endblock %}
  File "D:\Python27\microblog\app\templates\login.html", line 25, in block "content"
    <a href="{{url_for('reset_password_request')}}">Click to reset it</a>
  File "d:\python27\lib\site-packages\flask\helpers.py", line 333, in url_for
    return appctx.app.handle_url_build_error(error, endpoint, values)
  File "d:\python27\lib\site-packages\flask\app.py", line 1805, in handle_url_build_error
    reraise(exc_type, exc_value, tb)
  File "d:\python27\lib\site-packages\flask\helpers.py", line 323, in url_for
    force_external=external)
  File "d:\python27\lib\site-packages\werkzeug\routing.py", line 1768, in build
    raise BuildError(endpoint, values, method, self)
BuildError: Could not build url for endpoint 'reset_password_request'. Did you forget to specify values ['token']?
Microblog startup
Exception on /reset_password_request [POST]
Traceback (most recent call last):
  File "d:\python27\lib\site-packages\flask\app.py", line 1982, in wsgi_app
    response = self.full_dispatch_request()
  File "d:\python27\lib\site-packages\flask\app.py", line 1614, in full_dispatch_request
    rv = self.handle_user_exception(e)
  File "d:\python27\lib\site-packages\flask\app.py", line 1517, in handle_user_exception
    reraise(exc_type, exc_value, tb)
  File "d:\python27\lib\site-packages\flask\app.py", line 1612, in full_dispatch_request
    rv = self.dispatch_request()
  File "d:\python27\lib\site-packages\flask\app.py", line 1598, in dispatch_request
    return self.view_functions[rule.endpoint](**req.view_args)
  File "D:\Python27\microblog\app\routes.py", line 144, in reset_password_request
    send_password_reset_email(user)
NameError: global name 'send_password_reset_email' is not defined
Microblog startup
