Microblog startup
Exception on /edit_profile [POST]
Traceback (most recent call last):
  File "d:\python27\lib\site-packages\flask\app.py", line 1982, in wsgi_app
    response = self.full_dispatch_request()
  File "d:\python27\lib\site-packages\flask\app.py", line 1614, in full_dispatch_request
    rv = self.handle_user_exception(e)
  File "d:\python27\lib\site-packages\flask\app.py", line 1517, in handle_user_exception
    reraise(exc_type, exc_value, tb)
  File "d:\python27\lib\site-packages\flask\app.py", line 1612, in full_dispatch_request
    rv = self.dispatch_request()
  File "d:\python27\lib\site-packages\flask\app.py", line 1598, in dispatch_request
    return self.view_functions[rule.endpoint](**req.view_args)
  File "d:\python27\lib\site-packages\flask_login\utils.py", line 228, in decorated_view
    return func(*args, **kwargs)
  File "D:\Python27\microblog\app\routes.py", line 80, in edit_profile
    db.session.commit()
  File "d:\python27\lib\site-packages\sqlalchemy\orm\scoping.py", line 157, in do
    return getattr(self.registry(), name)(*args, **kwargs)
  File "d:\python27\lib\site-packages\sqlalchemy\orm\session.py", line 906, in commit
    self.transaction.commit()
  File "d:\python27\lib\site-packages\sqlalchemy\orm\session.py", line 461, in commit
    self._prepare_impl()
  File "d:\python27\lib\site-packages\sqlalchemy\orm\session.py", line 441, in _prepare_impl
    self.session.flush()
  File "d:\python27\lib\site-packages\sqlalchemy\orm\session.py", line 2171, in flush
    self._flush(objects)
  File "d:\python27\lib\site-packages\sqlalchemy\orm\session.py", line 2291, in _flush
    transaction.rollback(_capture_exception=True)
  File "d:\python27\lib\site-packages\sqlalchemy\util\langhelpers.py", line 66, in __exit__
    compat.reraise(exc_type, exc_value, exc_tb)
  File "d:\python27\lib\site-packages\sqlalchemy\orm\session.py", line 2255, in _flush
    flush_context.execute()
  File "d:\python27\lib\site-packages\sqlalchemy\orm\unitofwork.py", line 389, in execute
    rec.execute(self)
  File "d:\python27\lib\site-packages\sqlalchemy\orm\unitofwork.py", line 548, in execute
    uow
  File "d:\python27\lib\site-packages\sqlalchemy\orm\persistence.py", line 177, in save_obj
    mapper, table, update)
  File "d:\python27\lib\site-packages\sqlalchemy\orm\persistence.py", line 737, in _emit_update_statements
    execute(statement, multiparams)
  File "d:\python27\lib\site-packages\sqlalchemy\engine\base.py", line 945, in execute
    return meth(self, multiparams, params)
  File "d:\python27\lib\site-packages\sqlalchemy\sql\elements.py", line 263, in _execute_on_connection
    return connection._execute_clauseelement(self, multiparams, params)
  File "d:\python27\lib\site-packages\sqlalchemy\engine\base.py", line 1053, in _execute_clauseelement
    compiled_sql, distilled_params
  File "d:\python27\lib\site-packages\sqlalchemy\engine\base.py", line 1189, in _execute_context
    context)
  File "d:\python27\lib\site-packages\sqlalchemy\engine\base.py", line 1402, in _handle_dbapi_exception
    exc_info
  File "d:\python27\lib\site-packages\sqlalchemy\util\compat.py", line 203, in raise_from_cause
    reraise(type(exception), exception, tb=exc_tb, cause=cause)
  File "d:\python27\lib\site-packages\sqlalchemy\engine\base.py", line 1182, in _execute_context
    context)
  File "d:\python27\lib\site-packages\sqlalchemy\engine\default.py", line 470, in do_execute
    cursor.execute(statement, parameters)
IntegrityError: (sqlite3.IntegrityError) UNIQUE constraint failed: user.username [SQL: u'UPDATE user SET username=?, about_me=? WHERE user.id = ?'] [parameters: (u'susan', u'Happy and cool', 2)]
Microblog startup
Exception on /edit_profile [POST]
Traceback (most recent call last):
  File "d:\python27\lib\site-packages\flask\app.py", line 1982, in wsgi_app
    response = self.full_dispatch_request()
  File "d:\python27\lib\site-packages\flask\app.py", line 1614, in full_dispatch_request
    rv = self.handle_user_exception(e)
  File "d:\python27\lib\site-packages\flask\app.py", line 1517, in handle_user_exception
    reraise(exc_type, exc_value, tb)
  File "d:\python27\lib\site-packages\flask\app.py", line 1612, in full_dispatch_request
    rv = self.dispatch_request()
  File "d:\python27\lib\site-packages\flask\app.py", line 1598, in dispatch_request
    return self.view_functions[rule.endpoint](**req.view_args)
  File "d:\python27\lib\site-packages\flask_login\utils.py", line 228, in decorated_view
    return func(*args, **kwargs)
  File "D:\Python27\microblog\app\routes.py", line 80, in edit_profile
    db.session.commit()
  File "d:\python27\lib\site-packages\sqlalchemy\orm\scoping.py", line 157, in do
    return getattr(self.registry(), name)(*args, **kwargs)
  File "d:\python27\lib\site-packages\sqlalchemy\orm\session.py", line 906, in commit
    self.transaction.commit()
  File "d:\python27\lib\site-packages\sqlalchemy\orm\session.py", line 461, in commit
    self._prepare_impl()
  File "d:\python27\lib\site-packages\sqlalchemy\orm\session.py", line 441, in _prepare_impl
    self.session.flush()
  File "d:\python27\lib\site-packages\sqlalchemy\orm\session.py", line 2171, in flush
    self._flush(objects)
  File "d:\python27\lib\site-packages\sqlalchemy\orm\session.py", line 2291, in _flush
    transaction.rollback(_capture_exception=True)
  File "d:\python27\lib\site-packages\sqlalchemy\util\langhelpers.py", line 66, in __exit__
    compat.reraise(exc_type, exc_value, exc_tb)
  File "d:\python27\lib\site-packages\sqlalchemy\orm\session.py", line 2255, in _flush
    flush_context.execute()
  File "d:\python27\lib\site-packages\sqlalchemy\orm\unitofwork.py", line 389, in execute
    rec.execute(self)
  File "d:\python27\lib\site-packages\sqlalchemy\orm\unitofwork.py", line 548, in execute
    uow
  File "d:\python27\lib\site-packages\sqlalchemy\orm\persistence.py", line 177, in save_obj
    mapper, table, update)
  File "d:\python27\lib\site-packages\sqlalchemy\orm\persistence.py", line 737, in _emit_update_statements
    execute(statement, multiparams)
  File "d:\python27\lib\site-packages\sqlalchemy\engine\base.py", line 945, in execute
    return meth(self, multiparams, params)
  File "d:\python27\lib\site-packages\sqlalchemy\sql\elements.py", line 263, in _execute_on_connection
    return connection._execute_clauseelement(self, multiparams, params)
  File "d:\python27\lib\site-packages\sqlalchemy\engine\base.py", line 1053, in _execute_clauseelement
    compiled_sql, distilled_params
  File "d:\python27\lib\site-packages\sqlalchemy\engine\base.py", line 1189, in _execute_context
    context)
  File "d:\python27\lib\site-packages\sqlalchemy\engine\base.py", line 1402, in _handle_dbapi_exception
    exc_info
  File "d:\python27\lib\site-packages\sqlalchemy\util\compat.py", line 203, in raise_from_cause
    reraise(type(exception), exception, tb=exc_tb, cause=cause)
  File "d:\python27\lib\site-packages\sqlalchemy\engine\base.py", line 1182, in _execute_context
    context)
  File "d:\python27\lib\site-packages\sqlalchemy\engine\default.py", line 470, in do_execute
    cursor.execute(statement, parameters)
IntegrityError: (sqlite3.IntegrityError) UNIQUE constraint failed: user.username [SQL: u'UPDATE user SET username=?, about_me=? WHERE user.id = ?'] [parameters: (u'susan', u'Happy and cool', 2)]
Microblog startup
Microblog startup
Microblog startup
Microblog startup
Microblog startup
Microblog startup
Exception on / [GET]
Traceback (most recent call last):
  File "d:\python27\lib\site-packages\flask\app.py", line 1982, in wsgi_app
    response = self.full_dispatch_request()
  File "d:\python27\lib\site-packages\flask\app.py", line 1614, in full_dispatch_request
    rv = self.handle_user_exception(e)
  File "d:\python27\lib\site-packages\flask\app.py", line 1517, in handle_user_exception
    reraise(exc_type, exc_value, tb)
  File "d:\python27\lib\site-packages\flask\app.py", line 1612, in full_dispatch_request
    rv = self.dispatch_request()
  File "d:\python27\lib\site-packages\flask\app.py", line 1598, in dispatch_request
    return self.view_functions[rule.endpoint](**req.view_args)
  File "d:\python27\lib\site-packages\flask_login\utils.py", line 228, in decorated_view
    return func(*args, **kwargs)
  File "D:\Python27\microblog\app\routes.py", line 12, in index
    form =PostForm()
NameError: global name 'PostForm' is not defined
Exception on /index [GET]
Traceback (most recent call last):
  File "d:\python27\lib\site-packages\flask\app.py", line 1982, in wsgi_app
    response = self.full_dispatch_request()
  File "d:\python27\lib\site-packages\flask\app.py", line 1614, in full_dispatch_request
    rv = self.handle_user_exception(e)
  File "d:\python27\lib\site-packages\flask\app.py", line 1517, in handle_user_exception
    reraise(exc_type, exc_value, tb)
  File "d:\python27\lib\site-packages\flask\app.py", line 1612, in full_dispatch_request
    rv = self.dispatch_request()
  File "d:\python27\lib\site-packages\flask\app.py", line 1598, in dispatch_request
    return self.view_functions[rule.endpoint](**req.view_args)
  File "d:\python27\lib\site-packages\flask_login\utils.py", line 228, in decorated_view
    return func(*args, **kwargs)
  File "D:\Python27\microblog\app\routes.py", line 12, in index
    form =PostForm()
NameError: global name 'PostForm' is not defined
